// Explore Try-catch-finally to handle code with error



// const day = 'day the din';
// console.log(day);
// console.log(25);
// console.log(district);
// let district = 'bBaria';
// console.log(
//     61
// );




// try {
//     console.log('inside try');
// }
// catch (error) {
//     console.log('inside catch');
//     console.log(error);
// }
// finally {
//     console.log('finally done');
// }


// try {
//     console.log('inside try');
//     console.log(student);
// }
// catch (error) {
//     console.log('inside catch');
//     console.log(error);
// }
// finally {
//     console.log('finally done');
// }


// try {
//     console.log('inside try');
//     console.log(student);
// }
// catch (error) {
//     console.log('inside catch');
// }
// finally {
//     console.log('finally done');
// }


// try {
//     console.log('inside try');
//     console.log(district);
//     let district = 'bBaria';
//     console.log('after error');
// }
// catch (error) {
//     console.log('inside catch');
// }
// finally {
//     console.log('finally done');
// }
// console.log(100);


// try {
//     console.log('inside try');
//     console.log(district);
//     let district = 'bBaria';
//     console.log('after error');
// }
// catch (error) {
//     console.log('inside catch');
// }
// console.log(100);


try {
    console.log('inside try');
    console.log(district);
    let district = 'bBaria';
    console.log('after error');
}
finally {
    console.log('finally done');
}
console.log(100);